<?xml version="1.0"?>

<robot name="Bombel">

 <material name="blue">
   <color rgba="0 0 0.8 1"/>
 </material>

 <material name="yellow">
   <color rgba="255 255 0 1"/>
 </material>

 <material name="green">
   <color rgba="0 255 0 1"/>
 </material>


  <link name="base_link">
    <visual>
      <geometry>
        <cylinder length="0.2" radius="0.3"/>
      </geometry>
      <material name="blue"/>
    </visual>
  </link>

  <link name="rotating_base">
    <visual>
      <geometry>
        <cylinder length="0.1" radius="0.2"/>
      </geometry>
      <material name="blue"/>
      <origin xyz="0 0 0.15" rpy="0 0 0"/>
    </visual>
  </link>

<joint name="rotation_joint" type="revolute"> <!-- Jak ma sie nie ruszac to type="fixed" -->
    <parent link="base_link"/>
     <child link="rotating_base"/>
      <limit effort="1000.0" lower="-3.14" upper="3.14" velocity="0.5"/>
     <origin xyz="0 0 0" rpy="0 0 0"/>
    <axis xyz="0 0 1" />
  </joint>

  <link name="arm">
    <visual>
      <geometry>
        <cylinder length="0.5" radius="0.05"/>
      </geometry>
      <material name="yellow"/>
      <origin xyz="0.25 0 0" rpy="0 1.57 0"/>
    </visual>
  </link>

<joint name="shoulder" type="revolute">
    <parent link="rotating_base"/>
     <child link="arm"/>
      <limit effort="1000.0" lower="-0.6" upper="-1.57" velocity="0.5"/>
     <origin xyz="0 0 0.2" rpy="-1.57 0 0"/>
    <axis xyz="0 0 1" />
  </joint>

  <link name="forearm">
    <visual>
      <geometry>
        <cylinder length="0.3" radius="0.05"/>
      </geometry>
      <material name="green"/>
      <origin xyz="0.15 0 0" rpy="0 1.57 0"/>
    </visual>
  </link>

<joint name="elbow" type="revolute">
    <parent link="arm"/>
     <child link="forearm"/>
      <limit effort="1000.0" lower="0.0" upper="1.57" velocity="0.5"/>
     <origin xyz="0.5 0 0" rpy="0 0 0"/>
    <axis xyz="0 0 1" />
  </joint>


</robot>
