<?xml version="1.0"?>

<robot name="test_robot">

  <link name="link2" />

  <link name="link3">
    <visual>
      <geometry>
        <cylinder length="0.8" radius="0.1"/>
      </geometry>
    </visual>
  </link>

  <link name="link4" />

  <link name="base_link">
    <visual>
      <geometry>
        <cylinder length="0.6" radius="0.2"/>
      </geometry>
    </visual>
  </link>

  <joint name="joint1" type="continuous">
    <parent link="base_link"/>
    <child link="link2"/>
    <origin xyz="5 3 0" rpy="0 0 0" />
    <axis xyz="-0.9 0.15 0" />
  </joint>

  <joint name="joint2" type="continuous">
    <parent link="base_link"/>
    <child link="link3"/>
    <origin xyz="-2 5 0" rpy="0 0 1.57" />
    <axis xyz="-0.707 0.707 0" />
  </joint>

  <joint name="joint3" type="continuous">
    <parent link="link3"/>
    <child link="link4"/>
    <origin xyz="5 0 0" rpy="0 0 -1.57" />
    <axis xyz="0.707 -0.707 0" />
  </joint>

</robot>
