<?xml version="1.0"?>

<robot name="Mike">

 <material name="blue">
   <color rgba="0 0 0.8 1"/>
 </material>

 <material name="yellow">
   <color rgba="255 255 0 1"/>
 </material>

 <material name="green">
   <color rgba="0 255 0 1"/>
 </material>


  <link name="base_link">
    <visual>
      <geometry>
        <cylinder length="0.2" radius="0.3"/>
      </geometry>
   <material name="blue"/>
    </visual>
  </link>

  <link name="arm">
    <visual>
      <geometry>
        <cylinder length="0.5" radius="0.05"/>
      </geometry>
   <material name="yellow"/>
      <origin rpy="0 1.57 0" xyz="0.25 0 0"/>
    </visual>
  </link>

<joint name="shoulder" type="revolute">
    <parent link="base_link"/>
     <child link="arm"/>
      <limit effort="1000.0" lower="0.0" upper="-1.57" velocity="0.5"/>
     <origin xyz="0 0 0" rpy="-1.57 0 0"/>
    <axis xyz="0 0 1" />
  </joint>


</robot>
